INFO:fiftyone.zoo.datasets:Downloading split 'validation' to '/root/fiftyone/coco-2017/validation' if necessary
INFO:fiftyone.utils.coco:Found annotations at '/root/fiftyone/coco-2017/raw/instances_val2017.json'
INFO:fiftyone.utils.coco:Sufficient images already downloaded
INFO:fiftyone.zoo.datasets:Existing download of split 'validation' is sufficient
INFO:fiftyone.zoo.datasets:Loading existing dataset 'coco-2017-val'. To reload from disk, either delete the existing dataset or provide a custom `dataset_name` to use
WARNING:werkzeug: * Running on all addresses.
   WARNING: This is a development server. Do not use it in a production deployment.
INFO:werkzeug: * Running on http://172.19.0.4:5000/ (Press CTRL+C to quit)
DEBUG:asyncio:Using selector: EpollSelector
DEBUG:urllib3.connectionpool:Starting new HTTP connection (1): cloud:5000
INFO:werkzeug:172.19.0.2 - - [25/Feb/2022 11:36:54] "POST /endpoint HTTP/1.1" 200 -
DEBUG:urllib3.connectionpool:http://cloud:5000 "POST /endpoint HTTP/1.1" 200 27
ERROR:concurrent.futures:exception calling callback for <Future at 0x7f27292e9370 state=finished returned NoneType>
Traceback (most recent call last):
  File "/usr/local/lib/python3.9/concurrent/futures/_base.py", line 329, in _invoke_callbacks
    callback(self)
  File "/usr/local/lib/python3.9/asyncio/futures.py", line 398, in _call_set_state
    dest_loop.call_soon_threadsafe(_set_state, destination, source)
  File "/usr/local/lib/python3.9/asyncio/base_events.py", line 791, in call_soon_threadsafe
    self._check_closed()
  File "/usr/local/lib/python3.9/asyncio/base_events.py", line 510, in _check_closed
    raise RuntimeError('Event loop is closed')
RuntimeError: Event loop is closed
DEBUG:asyncio:Using selector: EpollSelector
DEBUG:urllib3.connectionpool:Starting new HTTP connection (1): cloud:5000
INFO:werkzeug:172.19.0.2 - - [25/Feb/2022 11:37:17] "POST /endpoint HTTP/1.1" 200 -
DEBUG:urllib3.connectionpool:http://cloud:5000 "POST /endpoint HTTP/1.1" 200 27
ERROR:concurrent.futures:exception calling callback for <Future at 0x7f269277f3a0 state=finished returned NoneType>
Traceback (most recent call last):
  File "/usr/local/lib/python3.9/concurrent/futures/_base.py", line 329, in _invoke_callbacks
    callback(self)
  File "/usr/local/lib/python3.9/asyncio/futures.py", line 398, in _call_set_state
    dest_loop.call_soon_threadsafe(_set_state, destination, source)
  File "/usr/local/lib/python3.9/asyncio/base_events.py", line 791, in call_soon_threadsafe
    self._check_closed()
  File "/usr/local/lib/python3.9/asyncio/base_events.py", line 510, in _check_closed
    raise RuntimeError('Event loop is closed')
RuntimeError: Event loop is closed
DEBUG:asyncio:Using selector: EpollSelector
